<?xml version='1.0'>
<sdf version='1.4'>
	<model name='ProjectRobot'>
		<link name='chassis'>
			<pose>0 0 0.136 0 0 0</pose>
			<!-- Iron Construction -->
			<collision name='IronLayer'>
				<pose>-0.12 0 0 0 0 0</pose>				
				<geometry>
					<box>
						<size>0.36 0.462 0.24</size>
					</box>
				</geometry>
			</collision>
			<visual name='IronLayer'>
				<pose>-0.12 0 0 0 0 0</pose>				
				<geometry>
					<box>
						<size>0.36 0.462 0.24</size>
					</box>
				</geometry>
			</visual>


			<!-- Upper Part of wheel -->
			<collision name='Upper_Wheel_Left'>
				<!-- This pose is respect to the center of the box -->
				<pose>0.185 0.2655 0.09 0 0 0</pose>
				<geometry>
					<box>
						<size>0.23 0.069 0.06</size>
					</box>
				</geometry>
			</collision>
			<visual name='Upper_Wheel_Left'>
				<!-- This pose is respect to the center of the box -->
				<pose>0.185 0.2655 0.09 0 0 0</pose>
				<geometry>
					<box>
						<size>0.23 0.069 0.06</size>
					</box>
				</geometry>
			</visual>			
			
			<!-- Upper Part of wheel-->
			<collision name='Upper_Wheel_Right'>
				<!-- This pose is respect to the center of the box -->				
				<pose>0.185 -0.2655 0.09 0 0 0</pose>
				<geometry>
					<box>
						<size>0.23 0.069 0.06</size>
					</box>
				</geometry>
			</collision>
			<visual name='Upper_Wheel_Right'>
				<!-- This pose is respect to the center of the box -->
				<pose>0.185 -0.2655 0.09 0 0 0</pose>
				<geometry>
					<box>
						<size>0.23 0.069 0.06</size>
					</box>
				</geometry>
			</visual>	

			<!-- Lateral flat piece between wheel and caster -->
			<collision name='Lateral_Flat_Left'>
				<!-- This pose is respect to the center of the box -->				
				<pose>-0.075 0.2655 0 0 0 0</pose>
				<geometry>
					<box>
						<size>0.29 0.069 0.24</size>
					</box>
				</geometry>
			</collision>
			<visual name='Lateral_Flat_Left'>
				<!-- This pose is respect to the center of the box -->
				<pose>-0.075 0.2655 0 0 0 0</pose>
				<geometry>
					<box>
						<size>0.29 0.069  0.24</size>
					</box>
				</geometry>
			</visual>

			<!-- Lateral flat piece between wheel and caster -->
			<collision name='Lateral_Flat_Right'>
				<!-- This pose is respect to the center of the box -->				
				<pose>-0.075 -0.2655 0 0 0 0</pose>
				<geometry>
					<box>
						<size>0.29 0.069  0.24</size>
					</box>
				</geometry>
			</collision>
			<visual name='Lateral_Flat_Right'>
				<!-- This pose is respect to the center of the box -->
				<pose>-0.075 -0.2655 0 0 0 0</pose>
				<geometry>
					<box>
						<size>0.29 0.069  0.24</size>
					</box>
				</geometry>
			</visual>

			<!-- Upper Part of caster -->
			<collision name='Upper_Caster_Left'>
				<!-- This pose is respect to the center of the box -->
				<pose>-0.26  0.2655 0.0175 0 0 0</pose>
				<geometry>
					<box>
						<size>0.08 0.069 0.205</size>
					</box>
				</geometry>
			</collision>
			<visual name='Upper_Caster_Left'>
				<!-- This pose is respect to the center of the box -->
				<pose>-0.26  0.2655 0.0175 0 0 0</pose>
				<geometry>
					<box>
						<size>0.08 0.069  0.205</size>
					</box>
				</geometry>
			</visual>

			<!-- Upper Part of caster -->
			<collision name='Upper_Caster_Right'>
				<!-- This pose is respect to the center of the box -->
				<pose>-0.26  -0.2655 0.0175 0 0 0</pose>
				<geometry>
					<box>
						<size>0.08 0.069 0.205</size>
					</box>
				</geometry>
			</collision>
			<visual name='Upper_Caster_Right'>
				<!-- This pose is respect to the center of the box -->
				<pose>-0.26  -0.2655 0.0175 0 0 0</pose>
				<geometry>
					<box>
						<size>0.08 0.069  0.205</size>
					</box>
				</geometry>
			</visual>
		
			<inertial>
				<mass> 7.8612 </mass>
			</inertial>
		</link>

		<link name='LeftMotorPlate'>
			<!-- Left Motor Plate-->
			<collision name='LeftMotorPlate'>
				<pose>0.18 -0.226 0.136 0 0 0</pose>
				<geometry>
					<box>
						<size>0.24 0.01 0.24</size>
					</box>
				</geometry>
			</collision>
			<visual name='LeftMotorPlate'>
				<pose>0.18 -0.226 0.136 0 0 0</pose>
				<geometry>
					<box>
						<size>0.24 0.01 0.24</size>
					</box>
				</geometry>
			</visual>
			<inertial>
				<mass> 0.8041 </mass>
			</inertial>

		</link>
		<joint type="fixed" name="LeftMotorPlateFix">
			<child>LeftMotorPlate</child>
			<parent>chassis</parent>
		</joint>

		<link name='RightMotorPlate'>
			<!-- Right Motor Plate-->
			<collision name='RightMotorPlate'>
				<pose>0.18 0.226 0.136 0 0 0</pose>
				<geometry>
					<box>
						<size>0.24 0.01 0.24</size>
					</box>
				</geometry>
			</collision>
			<visual name='RightMotorPlate'>
				<pose>0.18 0.226 0.136 0 0 0</pose>
				<geometry>
					<box>
						<size>0.24 0.01 0.24</size>
					</box>
				</geometry>
			</visual>
			<inertial>
				<mass> 0.8041 </mass>
			</inertial>
		</link>
		<joint type="fixed" name="RightMotorPlateFix">
			<child>RightMotorPlate</child>
			<parent>chassis</parent>
		</joint>

		<link name='LeftMotor'>
			<collision name='Left Motor'>
				<pose>0.25 -0.15 0.036 0 1.5707 1.5707</pose>
				<geometry>
					<cylinder>
						<radius>0.02</radius>
						<length>0.174</length>	
					</cylinder>
				</geometry>
			</collision>
			<visual name='Left Motor'>
				<pose>0.25 -0.15 0.036 0 1.5707 1.5707</pose>
				<geometry>
					<cylinder>
						<radius>0.02</radius>
						<length>0.174</length>	
					</cylinder>
				</geometry>
			</visual>
			<inertial>
				<mass> 0.41504 </mass>
			</inertial>
		</link>
		<joint type="fixed" name="LefttMotorFix">
			<child>LeftMotor</child>
			<parent>chassis</parent>
		</joint>

		<link name='RightMotor'>
			<collision name='Right Motor'>
				<pose>0.25 0.14 0.036 0 1.5707 1.5707</pose>
				<geometry>
					<cylinder>
						<radius>0.02</radius>
						<length>0.174</length>	
					</cylinder>
				</geometry>
			</collision>
			<visual name='Right Motor'>
				<pose>0.25 0.14 0.036 0 1.5707 1.5707</pose>
				<geometry>
					<cylinder>
						<radius>0.02</radius>
						<length>0.174</length>	
					</cylinder>
				</geometry>
			</visual>
			<inertial>
				<mass> 0.41504 </mass>
			</inertial>
		</link>

		<joint type="fixed" name="RightMotorFix">
			<child>RightMotor</child>
			<parent>chassis</parent>
		</joint>


		<link name='BaseLayer'>	
			<!-- Base Plane -->
			<collision name='BaseLayer'>
				<pose>0 0 0.016 0 0 0</pose>
				<geometry>
					<box>
						<size>0.60 0.462 0.01</size>
					</box>
				</geometry>
			</collision>
			<visual name='BaseLayer'>
				<pose>0 0 0.016 0 0 0</pose>
				<geometry>
					<box>
						<size>0.60 0.462 0.01</size>
					</box>
				</geometry>
			</visual>
			<inertial>
				<mass> 1.551 </mass>
			</inertial>
		</link>
		<joint type="fixed" name="BaseLayerFix">
			<child>BaseLayer</child>
			<parent>chassis</parent>
		</joint>

		<link name='Rot'>
			<collision name='Rot'>
				<pose>0.22 0 0.111 0 1.5707 1.5707</pose>
				<geometry>
					<cylinder>
						<radius>0.005</radius>
						<length>0.452</length>	
					</cylinder>
				</geometry>
			</collision>
			<visual name='Rot'>
				<pose>0.22 0 0.111 0 1.5707 1.5707</pose>
				<geometry>
					<cylinder>
						<radius>0.005</radius>
						<length>0.452</length>	
					</cylinder>
				</geometry>
			</visual>
			<inertial>
				<mass> 0.82663 </mass>
			</inertial>			
		</link>
		<joint type="fixed" name="RotFix">
			<child>Rot</child>
			<parent>chassis</parent>
		</joint>

		<link name='LeftWheel'>
			<!-- This pose respect to origin -->
			<pose> 0.185 -0.2525 0.095 0 1.5707 1.5707</pose>			
			<collision name='collision'>
				<geometry>
					<cylinder>
						<radius>0.095</radius>
						<length>0.038</length>
					</cylinder>
				</geometry>
			</collision>
			<visual name='visual'>
				<geometry>
					<cylinder>
						<radius>0.095</radius>
						<length>0.038</length>
					</cylinder>
				</geometry>
			</visual>	
			<inertial>
				<mass> 2.325 </mass>
			</inertial>

		</link>
		<link name='RightWheel'>
			<!-- This pose respect to origin -->			
			<pose> 0.185 0.2525 0.095 0 1.5707 1.5707</pose>			
			<collision name='collision'>
				<geometry>
					<cylinder>
						<radius>0.095</radius>
						<length>0.038</length>						
					</cylinder>
				</geometry>
			</collision>
			<visual name='visual'>
				<geometry>
					<cylinder>
						<radius>0.095</radius>
						<length>0.038</length>						
					</cylinder>
				</geometry>
			</visual>		
			<inertial>
				<mass> 2.325 </mass>
			</inertial>						
		</link>
		
		<link name='LeftCaster'>
			<pose> -0.275 -0.2525 0.025 0 0 0</pose>				
			<collision name='collision'>
				<geometry>
					<sphere>
						<radius>0.025</radius>
					</sphere>
				</geometry>
			</collision>
			<visual name='visual'>
				<geometry>
					<sphere>
						<radius>0.025</radius>
					</sphere>
				</geometry>
			</visual>		
			<inertial>
				<mass> 0.101553 </mass>
			</inertial>
		</link>
		<link name='RightCaster'>
			<pose> -0.275 0.2525 0.025 0 0 0</pose>				
			<collision name='collision'>
				<geometry>
					<sphere>
						<radius>0.025</radius>
					</sphere>
				</geometry>
			</collision>
			<visual name='visual'>
				<geometry>
					<sphere>
						<radius>0.025</radius>
					</sphere>
				</geometry>
			</visual>		
			<inertial>
				<mass> 0.101553 </mass>
			</inertial>
		</link>	

		<joint type="ball" name="left_caster_hinge">
			<child>LeftCaster</child>
			<parent>chassis</parent>
		</joint>
		<joint type="ball" name="right_caster_hinge">
			<child>RightCaster</child>
			<parent>chassis</parent>

		</joint>

		<joint type="revolute" name="left_wheel_hinge">
			<child>LeftWheel</child>
			<parent>LeftMotorPlate</parent>
			<axis>
				<xyz>0 1 0</xyz>
			</axis>
		</joint>
		<joint type="revolute" name="right_wheel_hinge">
			<child>RightWheel</child>
			<parent>RightMotorPlate</parent>
			<axis>
				<xyz>0 1 0</xyz>
			</axis>
		</joint>		

	</model>
</sdf>