<?xml version='1.0'>
<sdf version='1.4'>
	<world name="default">
		<!-- Ground Plane -->
		<include>
			<uri>model://ground_plane</uri>
		</include>

		<include>
			<uri>model://sun</uri>
		</include>

		<model name='ProjectRobot'>
			<link name='chassis'>
				<pose>0 0 0.136 0 0 0</pose>
				<!-- Iron Construction -->
				<collision name='IronLayer'>
					<pose>-0.12 0 0 0 0 0</pose>				
					<geometry>
						<box>
							<size>0.36 0.462 0.24</size>
						</box>
					</geometry>
				</collision>
				<visual name='IronLayer'>
					<pose>-0.12 0 0 0 0 0</pose>				
					<geometry>
						<box>
							<size>0.36 0.462 0.24</size>
						</box>
					</geometry>
				</visual>


				<!-- Upper Part of wheel -->
				<collision name='Upper_Wheel_Left'>
					<!-- This pose is respect to the center of the box -->
					<pose>0.185 0.2655 0.09 0 0 0</pose>
					<geometry>
						<box>
							<size>0.23 0.069 0.06</size>
						</box>
					</geometry>
				</collision>
				<visual name='Upper_Wheel_Left'>
					<!-- This pose is respect to the center of the box -->
					<pose>0.185 0.2655 0.09 0 0 0</pose>
					<geometry>
						<box>
							<size>0.23 0.069 0.06</size>
						</box>
					</geometry>
				</visual>			
				
				<!-- Upper Part of wheel-->
				<collision name='Upper_Wheel_Right'>
					<!-- This pose is respect to the center of the box -->				
					<pose>0.185 -0.2655 0.09 0 0 0</pose>
					<geometry>
						<box>
							<size>0.23 0.069 0.06</size>
						</box>
					</geometry>
				</collision>
				<visual name='Upper_Wheel_Right'>
					<!-- This pose is respect to the center of the box -->
					<pose>0.185 -0.2655 0.09 0 0 0</pose>
					<geometry>
						<box>
							<size>0.23 0.069 0.06</size>
						</box>
					</geometry>
				</visual>	

				<!-- Lateral flat piece between wheel and caster -->
				<collision name='Lateral_Flat_Left'>
					<!-- This pose is respect to the center of the box -->				
					<pose>-0.075 0.2655 0 0 0 0</pose>
					<geometry>
						<box>
							<size>0.29 0.069 0.24</size>
						</box>
					</geometry>
				</collision>
				<visual name='Lateral_Flat_Left'>
					<!-- This pose is respect to the center of the box -->
					<pose>-0.075 0.2655 0 0 0 0</pose>
					<geometry>
						<box>
							<size>0.29 0.069  0.24</size>
						</box>
					</geometry>
				</visual>

				<!-- Lateral flat piece between wheel and caster -->
				<collision name='Lateral_Flat_Right'>
					<!-- This pose is respect to the center of the box -->				
					<pose>-0.075 -0.2655 0 0 0 0</pose>
					<geometry>
						<box>
							<size>0.29 0.069  0.24</size>
						</box>
					</geometry>
				</collision>
				<visual name='Lateral_Flat_Right'>
					<!-- This pose is respect to the center of the box -->
					<pose>-0.075 -0.2655 0 0 0 0</pose>
					<geometry>
						<box>
							<size>0.29 0.069  0.24</size>
						</box>
					</geometry>
				</visual>

				<!-- Upper Part of caster -->
				<collision name='Upper_Caster_Left'>
					<!-- This pose is respect to the center of the box -->
					<pose>-0.26  0.2655 0.0175 0 0 0</pose>
					<geometry>
						<box>
							<size>0.08 0.069 0.205</size>
						</box>
					</geometry>
				</collision>
				<visual name='Upper_Caster_Left'>
					<!-- This pose is respect to the center of the box -->
					<pose>-0.26  0.2655 0.0175 0 0 0</pose>
					<geometry>
						<box>
							<size>0.08 0.069  0.205</size>
						</box>
					</geometry>
				</visual>

				<!-- Upper Part of caster -->
				<collision name='Upper_Caster_Right'>
					<!-- This pose is respect to the center of the box -->
					<pose>-0.26  -0.2655 0.0175 0 0 0</pose>
					<geometry>
						<box>
							<size>0.08 0.069 0.205</size>
						</box>
					</geometry>
				</collision>
				<visual name='Upper_Caster_Right'>
					<!-- This pose is respect to the center of the box -->
					<pose>-0.26  -0.2655 0.0175 0 0 0</pose>
					<geometry>
						<box>
							<size>0.08 0.069  0.205</size>
						</box>
					</geometry>
				</visual>

				<inertial>
					<mass> 7.8612 </mass>
					<pose> -0.010 0 -0.017 0 0 0</pose>
					<inertia>
						<ixx>0.2620398952</ixx>
						<ixy>0</ixy>
						<ixz>0</ixz>
						<iyy>0.2620398952</iyy>
						<iyz>0</iyz>
						<izz>0.4716718113</izz>
					</inertia>
				</inertial>
			</link>

			<link name='LeftMotorPlate'>
				<pose>0.18 -0.226 0.136 0 0 0</pose>
				<!-- Left Motor Plate-->
				<collision name='LeftMotorPlate'>
					<geometry>
						<box>
							<size>0.24 0.01 0.24</size>
						</box>
					</geometry>
				</collision>
				<visual name='LeftMotorPlate'>
					<geometry>
						<box>
							<size>0.24 0.01 0.24</size>
						</box>
					</geometry>
				</visual>
				<inertial>
					<mass> 0.8041 </mass>
				<!-- <inertia>
						<ixx>0.003866379287</ixx>
						<ixy>0</ixy>
						<ixz>0</ixz>
						<iyy>0.007719356912</iyy>
						<iyz>0</iyz>
						<izz>0.003866379287</izz>
					</inertia> -->
					<inertia>
						<ixx>0</ixx>
						<ixy>0</ixy>
						<ixz>0</ixz>
						<iyy>0</iyy>
						<iyz>0</iyz>
						<izz>0</izz>
					</inertia>
				</inertial>

			</link>
			<joint type="fixed" name="LeftMotorPlateFix">
				<child>LeftMotorPlate</child>
				<parent>chassis</parent>
			</joint>

			<link name='RightMotorPlate'>
				<!-- Right Motor Plate-->
				<pose>0.18 0.226 0.136 0 0 0</pose>				
				<collision name='RightMotorPlate'>
					<geometry>
						<box>
							<size>0.24 0.01 0.24</size>
						</box>
					</geometry>
				</collision>
				<visual name='RightMotorPlate'>
					<geometry>
						<box>
							<size>0.24 0.01 0.24</size>
						</box>
					</geometry>
				</visual>
				<inertial>
					<mass> 0.8041 </mass>
	            <!-- <inertia>
						<ixx>0.003866379287</ixx>
						<ixy>0</ixy>
						<ixz>0</ixz>
						<iyy>0.007719356912</iyy>
						<iyz>0</iyz>
						<izz>0.003866379287</izz>
					</inertia> -->
					<inertia>
						<ixx>0</ixx>
						<ixy>0</ixy>
						<ixz>0</ixz>
						<iyy>0</iyy>
						<iyz>0</iyz>
						<izz>0</izz>
					</inertia>
				</inertial>
			</link>
			<joint type="fixed" name="RightMotorPlateFix">
				<child>RightMotorPlate</child>
				<parent>chassis</parent>
			</joint>

			<link name='SidePlate'>
				<pose>-0.120 0.220 0.136 0 0 0</pose>				
				<collision name='SidePlate'>
					<geometry>
						<box>
							<size>0.350 0.01 0.24</size>
						</box>
					</geometry>
				</collision>
				<visual name='SidePlate'>
					<geometry>
						<box>
							<size>0.350 0.01 0.24</size>
						</box>
					</geometry>
				</visual>
				<inertial>
					<mass> 0.31054 </mass>
				</inertial>
			</link>
			<joint type="fixed" name="SidePlateFix">
				<child>SidePlate</child>
				<parent>chassis</parent>
			</joint>

			<link name='LeftMotor'>
				<pose>0.25 -0.15 0.036 0 1.5707 1.5707</pose>			
				<collision name='Left Motor'>
					<geometry>
						<cylinder>
							<radius>0.02</radius>
							<length>0.174</length>	
						</cylinder>
					</geometry>
				</collision>
				<visual name='Left Motor'>
					<geometry>
						<cylinder>
							<radius>0.02</radius>
							<length>0.174</length>	
						</cylinder>
					</geometry>
				</visual>
				<inertial>
					<mass> 0.41504 </mass>
					<inertia>
						<ixx>0</ixx>
						<ixy>0</ixy>
						<ixz>0</ixz>
						<iyy>0</iyy>
						<iyz>0</iyz>
						<izz>0</izz>
					</inertia>
				<!-- <inertia>
						<ixx>0.00108864992</ixx>
						<ixy>0</ixy>
						<ixz>0</ixz>
						<iyy>0.00108864992</iyy>
						<iyz>0</iyz>
						<izz>0.00108864992</izz>
					</inertia> -->
				</inertial>
			</link>
			<joint type="fixed" name="LefttMotorFix">
				<child>LeftMotor</child>
				<parent>chassis</parent>
			</joint>

			<link name='RightMotor'>
				<pose>0.25 0.14 0.036 0 1.5707 1.5707</pose>		
				<collision name='Right Motor'>
					<geometry>
						<cylinder>
							<radius>0.02</radius>
							<length>0.174</length>	
						</cylinder>
					</geometry>
				</collision>
				<visual name='Right Motor'>
					<geometry>
						<cylinder>
							<radius>0.02</radius>
							<length>0.174</length>	
						</cylinder>
					</geometry>
				</visual>
				<inertial>
					<mass> 0.41504 </mass>
					<inertia>
						<ixx>0</ixx>
						<ixy>0</ixy>
						<ixz>0</ixz>
						<iyy>0</iyy>
						<iyz>0</iyz>
						<izz>0</izz>
					</inertia>
				<!-- <inertia>
						<ixx>0.00108864992</ixx>
						<ixy>0</ixy>
						<ixz>0</ixz>
						<iyy>0.00108864992</iyy>
						<iyz>0</iyz>
						<izz>0.00108864992</izz>
					</inertia> -->
				</inertial>
			</link>

			<joint type="fixed" name="RightMotorFix">
				<child>RightMotor</child>
				<parent>chassis</parent>
			</joint>


			<link name='BaseLayer'>	
				<!-- Base Plane -->
				<pose>0 0 0.016 0 0 0</pose>
				<collision name='BaseLayer'>
					<geometry>
						<box>
							<size>0.60 0.462 0.01</size>
						</box>
					</geometry>
				</collision>
				<visual name='BaseLayer'>
					<geometry>
						<box>
							<size>0.60 0.462 0.01</size>
						</box>
					</geometry>
				</visual>
				<inertial>
					<mass> 1.551 </mass>
					<inertia>
						<ixx>0</ixx>
						<ixy>0</ixy>
						<ixz>0</ixz>
						<iyy>0</iyy>
						<iyz>0</iyz>
						<izz>0</izz>
					</inertia>
				<!-- <inertia>
						<ixx>0.02760055096</ixx>
						<ixy>0</ixy>
						<ixz>0</ixz>
						<iyy>0.04654290638</iyy>
						<iyz>0</iyz>
						<izz>0.07411760735</izz>
					</inertia> -->
				</inertial>
			</link>
			<joint type="fixed" name="BaseLayerFix">
				<child>BaseLayer</child>
				<parent>chassis</parent>
			</joint>

			<link name='Rot'>
				<pose>0.22 0 0.111 0 1.5707 1.5707</pose>
				<collision name='Rot'>
					<geometry>
						<cylinder>
							<radius>0.005</radius>
							<length>0.452</length>	
						</cylinder>
					</geometry>
				</collision>
				<visual name='Rot'>
					<geometry>
						<cylinder>
							<radius>0.005</radius>
							<length>0.452</length>	
						</cylinder>
					</geometry>
				</visual>
				<inertial>
					<mass> 0.82663 </mass>
					<inertia>
						<ixx>0</ixx>
						<ixy>0</ixy>
						<ixz>0</ixz>
						<iyy>0</iyy>
						<iyz>0</iyz>
						<izz>0</izz>
					</inertia>
				<!-- <inertia>
						<ixx>0.01407881773</ixx>
						<ixy>0</ixy>
						<ixz>0</ixz>
						<iyy>0.01407881773</iyy>
						<iyz>0</iyz>
						<izz>0.01407881773</izz>
					</inertia> -->
				</inertial>			
			</link>
			<joint type="fixed" name="RotFix">
				<child>Rot</child>
				<parent>chassis</parent>
			</joint>

			<link name='LeftWheel'>
				<!-- This pose respect to origin -->
				<pose> 0.185 -0.2525 0.095 0 1.5707 1.5707</pose>			
				<collision name='collision'>
					<geometry>
						<cylinder>
							<radius>0.095</radius>
							<length>0.038</length>
						</cylinder>
					</geometry>
					<surface>
						<friction>
							<ode>
								<mu>0.6</mu>
								<mu2>0.85</mu2>
							</ode>
						</friction>
					</surface>
				</collision>
				<visual name='visual'>
					<geometry>
						<cylinder>
							<radius>0.095</radius>
							<length>0.038</length>
						</cylinder>
					</geometry>
					<material>
						<ambient>0 0 0 1</ambient>
						<diffuse>0 0 0 1</diffuse>
						<specular>0 0 0 0</specular>
						<emissive>0 0 0 1</emissive>
					</material>
				</visual>	
				<inertial>
					<mass> 2.325 </mass>
					<inertia>
						<ixx>0.00552555625</ixx>
						<ixy>0</ixy>
						<ixz>0</ixz>
						<iyy>0.00552555625</iyy>
						<iyz>0</iyz>
						<izz>0.00552555625</izz>
					</inertia>
				</inertial>

			</link>
			<link name='RightWheel'>
				<!-- This pose respect to origin -->			
				<pose> 0.185 0.2525 0.095 0 1.5707 1.5707</pose>			
				<collision name='collision'>
					<geometry>
						<cylinder>
							<radius>0.095</radius>
							<length>0.038</length>						
						</cylinder>
					</geometry>
					<surface>
						<friction>
							<ode>
								<mu>0.6</mu>
								<mu2>0.85</mu2>
							</ode>
						</friction>
					</surface>
				</collision>
				<visual name='visual'>
					<geometry>
						<cylinder>
							<radius>0.095</radius>
							<length>0.038</length>						
						</cylinder>
					</geometry>
					<material>
						<ambient>0 0 0 1</ambient>
						<diffuse>0 0 0 1</diffuse>
						<specular>0 0 0 0</specular>
						<emissive>0 0 0 1</emissive>
					</material>
				</visual>		
				<inertial>
					<mass> 2.325 </mass>
					<inertia>
						<ixx>0.00552555625</ixx>
						<ixy>0</ixy>
						<ixz>0</ixz>
						<iyy>0.00552555625</iyy>
						<iyz>0</iyz>
						<izz>0.00552555625</izz>
					</inertia>
				</inertial>						
			</link>
			
			<link name='LeftCaster'>
				<pose> -0.275 -0.2525 0.025 0 0 0</pose>				
				<collision name='collision'>
					<geometry>
						<sphere>
							<radius>0.025</radius>
						</sphere>
					</geometry>
					<surface>
						<friction>
							<ode>
								<mu>0.6</mu>
								<mu2>0.85</mu2>
							</ode>
						</friction>
					</surface>
				</collision>
				<visual name='visual'>
					<geometry>
						<sphere>
							<radius>0.025</radius>
						</sphere>
					</geometry>
				</visual>		
				<inertial>
					<mass> 0.101553 </mass>
					<inertia>
						<ixx>0.00002538825</ixx>
						<ixy>0</ixy>
						<ixz>0</ixz>
						<iyy>0.00002538825</iyy>
						<iyz>0</iyz>
						<izz>0.00002538825</izz>
					</inertia>
				</inertial>
			</link>
			<link name='RightCaster'>
				<pose> -0.275 0.2525 0.025 0 0 0</pose>				
				<collision name='collision'>
					<geometry>
						<sphere>
							<radius>0.025</radius>
						</sphere>
					</geometry>
					<surface>
						<friction>
							<ode>
								<mu>0.6</mu>
								<mu2>0.85</mu2>
							</ode>
						</friction>
					</surface>
				</collision>
				<visual name='visual'>
					<geometry>
						<sphere>
							<radius>0.025</radius>
						</sphere>
					</geometry>
				</visual>		
				<inertial>
					<mass> 0.101553 </mass>
					<inertia>
						<ixx>0.00002538825</ixx>
						<ixy>0</ixy>
						<ixz>0</ixz>
						<iyy>0.00002538825</iyy>
						<iyz>0</iyz>
						<izz>0.00002538825</izz>
					</inertia>
				</inertial>
			</link>	

			<joint type="ball" name="left_caster_hinge">
				<child>LeftCaster</child>
				<parent>chassis</parent>
			</joint>
			<joint type="ball" name="right_caster_hinge">
				<child>RightCaster</child>
				<parent>chassis</parent>
			</joint>

			<joint type="revolute" name="left_wheel_hinge">
				<child>LeftWheel</child>
				<parent>LeftMotorPlate</parent>
				<axis>
					<xyz>0 1 0</xyz>
				</axis>
			</joint>
			<joint type="revolute" name="right_wheel_hinge">
				<child>RightWheel</child>
				<parent>RightMotorPlate</parent>
				<axis>
					<xyz>0 1 0</xyz>
				</axis>
			</joint>		

			
			<plugin name="encoder" filename="libencoder.so"/>
			<plugin name="differential_drive_controller" filename="libgazebo_ros_diff_drive.so">
				<alwaysOn>true</alwaysOn>
				<updateRate>20</updateRate>
				<leftJoint>right_wheel_hinge</leftJoint>
				<rightJoint>left_wheel_hinge</rightJoint>
				<wheelSeparation>0.462</wheelSeparation>
				<wheelDiameter>0.19</wheelDiameter>
				<torque>20</torque>
				<commandTopic>cmd_vel</commandTopic>
				<odometryTopic>odom</odometryTopic>
				<odometryFrame>odom</odometryFrame>
				<robotBaseFrame>base_footprint</robotBaseFrame>
			</plugin>
		</model>
		<physics type='ode'>
			<real_time_factor>1.000000</real_time_factor>
			<real_time_update_rate>1000.000000</real_time_update_rate>
			<gravity>0.000000 0.000000 -9.800000</gravity>
		</physics>
	</world>
</sdf>